Exception in thread Thread-1:
Traceback (most recent call last):
  File "/usr/lib/python3.9/threading.py", line 954, in _bootstrap_inner
    self.run()
  File "/usr/lib/python3.9/threading.py", line 892, in run
    self._target(*self._args, **self._kwargs)
  File "/home/pi/helicorder/code/seislog.py", line 98, in socket_worker
    conn.send(data)
TimeoutError: [Errno 110] Connection timed out
